<?xml version="1.0" ?>
<robot name="">
	<link name="Base">
		<inertial>
			<origin rpy="0.00000 0.00000 0.00000" xyz="0.00000 0.00000 0.00000"/>
			<mass value="1"/>
			<inertia ixx="0" ixy="0" ixz="0" iyy="0" iyz="0" izz="0"/>
		</inertial>
		<visual>
			<origin rpy="0.00000 0.00000 0.00000" xyz="0.00000 0.00000 0.00000"/>
			<geometry>
				<box size="1.00000 1.00000 1.00000"/>
			</geometry>
			<material name="">
				<color rgba="1.00000 0.00000 0.00000 1.00000" />
			</material>
		</visual>
		<collision>
			<origin rpy="0.00000 0.00000 0.00000" xyz="0.00000 0.00000 0.00000"/>
			<geometry>
				<box size="1.00000 1.00000 1.00000"/>
			</geometry>
		</collision>
	</link>
	<link name="S_Base/Limb1">
		<inertial>
			<origin rpy="0.00000 0.00000 0.00000" xyz="0.00000 0.00000 0.00000"/>
			<mass value="1"/>
			<inertia ixx="0" ixy="0" ixz="0" iyy="0" iyz="0" izz="0"/>
		</inertial>
		<visual>
			<origin rpy="0.00000 0.00000 0.00000" xyz="0.00000 0.00000 0.00000"/>
			<geometry>
				<sphere radius="0.5"/>
			</geometry>
			<material name="">
				<color rgba="1.00000 0.00000 0.00000 1.00000" />
			</material>
		</visual>
		<collision>
			<origin rpy="0.00000 0.00000 0.00000" xyz="0.00000 0.00000 0.00000"/>
			<geometry>
				<sphere radius="0.5"/>
			</geometry>
		</collision>
	</link>
	<link name="Limb1">
		<inertial>
			<origin rpy="0.00000 0.00000 0.00000" xyz="0.00000 0.00000 0.00000"/>
			<mass value="1"/>
			<inertia ixx="0" ixy="0" ixz="0" iyy="0" iyz="0" izz="0"/>
		</inertial>
		<visual>
			<origin rpy="0.00000 0.00000 0.00000" xyz="0.00000 0.00000 0.50000"/>
			<geometry>
				<box size="1.00000 1.00000 1.00000"/>
			</geometry>
			<material name="">
				<color rgba="1.00000 0.00000 0.00000 1.00000" />
			</material>
		</visual>
		<collision>
			<origin rpy="0.00000 0.00000 0.00000" xyz="0.00000 0.00000 0.50000"/>
			<geometry>
				<box size="1.00000 1.00000 1.00000"/>
			</geometry>
		</collision>
	</link>
	<link name="S_Base/Limb2">
		<inertial>
			<origin rpy="0.00000 0.00000 0.00000" xyz="0.00000 0.00000 0.00000"/>
			<mass value="1"/>
			<inertia ixx="0" ixy="0" ixz="0" iyy="0" iyz="0" izz="0"/>
		</inertial>
		<visual>
			<origin rpy="0.00000 0.00000 0.00000" xyz="0.00000 0.00000 0.00000"/>
			<geometry>
				<sphere radius="0.5"/>
			</geometry>
			<material name="">
				<color rgba="1.00000 0.00000 0.00000 1.00000" />
			</material>
		</visual>
		<collision>
			<origin rpy="0.00000 0.00000 0.00000" xyz="0.00000 0.00000 0.00000"/>
			<geometry>
				<sphere radius="0.5"/>
			</geometry>
		</collision>
	</link>
	<link name="Limb2">
		<inertial>
			<origin rpy="0.00000 0.00000 0.00000" xyz="0.00000 0.00000 0.00000"/>
			<mass value="1"/>
			<inertia ixx="0" ixy="0" ixz="0" iyy="0" iyz="0" izz="0"/>
		</inertial>
		<visual>
			<origin rpy="0.00000 0.00000 0.00000" xyz="0.00000 0.00000 1.00000"/>
			<geometry>
				<box size="1.00000 1.00000 2.00000"/>
			</geometry>
			<material name="">
				<color rgba="1.00000 0.00000 0.00000 1.00000" />
			</material>
		</visual>
		<collision>
			<origin rpy="0.00000 0.00000 0.00000" xyz="0.00000 0.00000 1.00000"/>
			<geometry>
				<box size="1.00000 1.00000 2.00000"/>
			</geometry>
		</collision>
	</link>
	<link name="S_Base/Limb3">
		<inertial>
			<origin rpy="0.00000 0.00000 0.00000" xyz="0.00000 0.00000 0.00000"/>
			<mass value="1"/>
			<inertia ixx="0" ixy="0" ixz="0" iyy="0" iyz="0" izz="0"/>
		</inertial>
		<visual>
			<origin rpy="0.00000 0.00000 0.00000" xyz="0.00000 0.00000 0.00000"/>
			<geometry>
				<sphere radius="0.5"/>
			</geometry>
			<material name="">
				<color rgba="1.00000 0.00000 0.00000 1.00000" />
			</material>
		</visual>
		<collision>
			<origin rpy="0.00000 0.00000 0.00000" xyz="0.00000 0.00000 0.00000"/>
			<geometry>
				<sphere radius="0.5"/>
			</geometry>
		</collision>
	</link>
	<link name="Limb3">
		<inertial>
			<origin rpy="0.00000 0.00000 0.00000" xyz="0.00000 0.00000 0.00000"/>
			<mass value="1"/>
			<inertia ixx="0" ixy="0" ixz="0" iyy="0" iyz="0" izz="0"/>
		</inertial>
		<visual>
			<origin rpy="0.00000 0.00000 0.00000" xyz="0.00000 0.00000 1.00000"/>
			<geometry>
				<box size="1.00000 1.00000 2.00000"/>
			</geometry>
			<material name="">
				<color rgba="1.00000 0.00000 0.00000 1.00000" />
			</material>
		</visual>
		<collision>
			<origin rpy="0.00000 0.00000 0.00000" xyz="0.00000 0.00000 1.00000"/>
			<geometry>
				<box size="1.00000 1.00000 2.00000"/>
			</geometry>
		</collision>
	</link>
<joint name="Jx_Base/Limb1" type="continuous">
		<parent link="Base"/>
		<child link="S_Base/Limb1"/>
		<dynamics damping="1.0" friction="0.0001"/>
		<origin rpy="0.00000 0.00000 0.00000" xyz="0.00000 0.00000 0.50000"/>
		<axis xyz="1.00000 0.00000 0.00000"/>
	</joint>
<joint name="Jy_Base/Limb1" type="continuous">
		<parent link="S_Base/Limb1"/>
		<child link="Limb1"/>
		<dynamics damping="1.0" friction="0.0001"/>
		<origin rpy="0.00000 0.00000 0.00000" xyz="0.00000 0.00000 0.00000"/>
		<axis xyz="0.00000 1.00000 0.00000"/>
	</joint>
<joint name="Jx_Base/Limb2" type="continuous">
		<parent link="Base"/>
		<child link="S_Base/Limb2"/>
		<dynamics damping="1.0" friction="0.0001"/>
		<origin rpy="0.00000 1.57080 0.00000" xyz="0.50000 0.00000 0.00000"/>
		<axis xyz="1.00000 0.00000 0.00000"/>
	</joint>
<joint name="Jy_Base/Limb2" type="continuous">
		<parent link="S_Base/Limb2"/>
		<child link="Limb2"/>
		<dynamics damping="1.0" friction="0.0001"/>
		<origin rpy="0.00000 0.00000 0.00000" xyz="0.00000 0.00000 0.00000"/>
		<axis xyz="0.00000 1.00000 0.00000"/>
	</joint>
<joint name="Jx_Base/Limb3" type="continuous">
		<parent link="Base"/>
		<child link="S_Base/Limb3"/>
		<dynamics damping="1.0" friction="0.0001"/>
		<origin rpy="0.00000 -1.57080 0.00000" xyz="-0.50000 0.00000 0.00000"/>
		<axis xyz="1.00000 0.00000 0.00000"/>
	</joint>
<joint name="Jy_Base/Limb3" type="continuous">
		<parent link="S_Base/Limb3"/>
		<child link="Limb3"/>
		<dynamics damping="1.0" friction="0.0001"/>
		<origin rpy="0.00000 0.00000 0.00000" xyz="0.00000 0.00000 0.00000"/>
		<axis xyz="0.00000 1.00000 0.00000"/>
	</joint>
</robot>
